<?xml version="1.0" ?>
<!-- =================================================================================== -->
<!-- |    This document was autogenerated by xacro from om_v01.urdf.xacro              | -->
<!-- |    EDITING THIS FILE BY HAND IS NOT RECOMMENDED                                 | -->
<!-- =================================================================================== -->
<!-- Open_Manipulator Chain -->
<robot name="om">
  <link name="world"/>
  <joint name="world_joint" type="fixed">
    <origin rpy="0 0 0" xyz="0 0.0 0.0"/>
    <parent link="world"/>
    <child link="link1"/>
  </joint>
  <!-- Link 1 -->
  <link name="link1">
    <visual>
      <origin rpy="0 0 0" xyz="0 0 0"/>
      <geometry>
        <mesh filename="package://om_urdf/meshes/stl/chain_link1.stl" scale="0.001 0.001 0.001"/>
      </geometry>
      <material name="grey"/>
    </visual>
    <collision>
      <origin rpy="0 0 0" xyz="0 0 0"/>
      <geometry>
        <mesh filename="package://om_urdf/meshes/stl/chain_link1.stl" scale="0.001 0.001 0.001"/>
      </geometry>
    </collision>
    <inertial>
      <origin xyz="3.0876154e-04 0.0000000e+00 -1.2176461e-04"/>
      <mass value="7.9119962e-02"/>
      <inertia ixx="1.2505234e-05" ixy="0.0" ixz="-1.7855208e-07" iyy="2.1898364e-05" iyz="0.0" izz="1.9267361e-05"/>
    </inertial>
  </link>
  <!-- Joint 1 -->
  <joint name="joint1" type="revolute">
    <parent link="link1"/>
    <child link="link2"/>
    <origin rpy="0 0 0" xyz="0.0 0.0 0.036"/>
    <axis xyz="0 0 1"/>
    <limit effort="1" lower="-2.827433388230814" upper="2.827433388230814" velocity="4.8"/>
  </joint>
  <!--  Link 2 -->
  <link name="link2">
    <visual>
      <origin rpy="0 0 0" xyz="0 0 0.0"/>
      <geometry>
        <mesh filename="package://om_urdf/meshes/stl/chain_link2.stl" scale="0.001 0.001 0.001"/>
      </geometry>
      <material name="grey"/>
    </visual>
    <collision>
      <origin rpy="0 0 0" xyz="0 0 0.0"/>
      <geometry>
        <mesh filename="package://om_urdf/meshes/stl/chain_link2.stl" scale="0.001 0.001 0.001"/>
      </geometry>
    </collision>
    <inertial>
      <origin xyz="-3.0184870e-04 5.4043684e-04 0.047433463999999995"/>
      <mass value="9.8406837e-02"/>
      <inertia ixx="3.4543422e-05" ixy="-1.6031095e-08" ixz="-3.8375155e-07" iyy="3.2689329e-05" iyz="2.8511935e-08" izz="1.8850320e-05"/>
    </inertial>
  </link>
  <!--  Joint 2 -->
  <joint name="joint2" type="revolute">
    <parent link="link2"/>
    <child link="link3"/>
    <origin rpy="0 0 0" xyz="0.0 0.0 0.05675"/>
    <axis xyz="0 1 0"/>
    <limit effort="1" lower="-1.790707812546182" upper="1.5707963267948966" velocity="4.8"/>
  </joint>
  <!--  Link 3 -->
  <link name="link3">
    <visual>
      <origin rpy="0 0 0" xyz="0 0 0"/>
      <geometry>
        <mesh filename="package://om_urdf/meshes/stl/chain_link3.stl" scale="0.001 0.001 0.001"/>
      </geometry>
      <material name="grey"/>
    </visual>
    <collision>
      <origin rpy="0 0 0" xyz="0 0 0"/>
      <geometry>
        <mesh filename="package://om_urdf/meshes/stl/chain_link3.stl" scale="0.001 0.001 0.001"/>
      </geometry>
    </collision>
    <inertial>
      <origin xyz="1.0308393e-02 3.7743363e-04 1.0170197e-01"/>
      <mass value="1.3850917e-01"/>
      <inertia ixx="3.3055381e-04" ixy="-9.7940978e-08" ixz="-3.8505711e-05" iyy="3.4290447e-04" iyz="-1.5717516e-06" izz="6.0346498e-05"/>
    </inertial>
  </link>
  <!--  Joint 3 -->
  <joint name="joint3" type="revolute">
    <parent link="link3"/>
    <child link="link4"/>
    <origin rpy="0 0 0" xyz="0.024 0 0.161714"/>
    <axis xyz="0 1 0"/>
    <limit effort="1" lower="-1.790707812546182" upper="1.382300767579509" velocity="4.8"/>
  </joint>
  <!--  Link 4 -->
  <link name="link4">
    <visual>
      <origin rpy="0 0 0" xyz="0 0 0"/>
      <geometry>
        <mesh filename="package://om_urdf/meshes/stl/chain_link4.stl" scale="0.001 0.001 0.001"/>
      </geometry>
      <material name="grey"/>
    </visual>
    <collision>
      <origin rpy="0 0 0" xyz="0 0 0"/>
      <geometry>
        <mesh filename="package://om_urdf/meshes/stl/chain_link4.stl" scale="0.001 0.001 0.001"/>
      </geometry>
    </collision>
    <inertial>
      <origin xyz="9.0909590e-02 3.8929816e-04 2.2413279e-04"/>
      <mass value="1.3274562e-01"/>
      <inertia ixx="3.0654178e-05" ixy="-1.2764155e-06" ixz="-2.6874417e-07" iyy="2.4230292e-04" iyz="1.1559550e-08" izz="2.5155057e-04"/>
    </inertial>
  </link>
  <!--  Joint 4 -->
  <joint name="joint4" type="revolute">
    <parent link="link4"/>
    <child link="link5"/>
    <origin rpy="0 0 0" xyz="0.1235 0.0 0.0"/>
    <axis xyz="0 1 0"/>
    <limit effort="1" lower="-1.790707812546182" upper="2.0420352248333655" velocity="4.8"/>
  </joint>
  <!--  Link 5 -->
  <link name="link5">
    <visual>
      <origin rpy="0 0 0" xyz="0 0 0"/>
      <geometry>
        <mesh filename="package://om_urdf/meshes/stl/chain_link5.stl" scale="0.001 0.001 0.001"/>
      </geometry>
      <material name="grey"/>
    </visual>
    <collision>
      <origin rpy="0 0 0" xyz="0 0 0"/>
      <geometry>
        <mesh filename="package://om_urdf/meshes/stl/chain_link5.stl" scale="0.001 0.001 0.001"/>
      </geometry>
    </collision>
    <inertial>
      <origin xyz="0 0 0"/>
      <mass value="1.0e-03"/>
      <inertia ixx="1.0e-03" ixy="0.0" ixz="0.0" iyy="1.0e-03" iyz="0.0" izz="1.0e-03"/>
    </inertial>
  </link>
  <!--  Joint 5 -->
  <joint name="joint5" type="revolute">
    <parent link="link5"/>
    <child link="link6"/>
    <origin rpy="0 0 0" xyz="0.064 0.0 0.0"/>
    <axis xyz="1 0 0"/>
    <limit effort="1" lower="-3.141592653589793" upper="3.141592653589793" velocity="4.8"/>
  </joint>
  <!--  Link 6 -->
  <link name="link6">
    <visual>
      <origin rpy="0 0 0" xyz="0 0 0"/>
      <geometry>
        <mesh filename="package://om_urdf/meshes/stl/chain_link6.stl" scale="0.001 0.001 0.001"/>
      </geometry>
      <material name="grey"/>
    </visual>
    <collision>
      <origin rpy="0 0 0" xyz="0 0 0"/>
      <geometry>
        <mesh filename="package://om_urdf/meshes/stl/chain_link6.stl" scale="0.001 0.001 0.001"/>
      </geometry>
    </collision>
    <inertial>
      <origin xyz="0 0 0"/>
      <mass value="1.0e-03"/>
      <inertia ixx="1.0e-03" ixy="0.0" ixz="0.0" iyy="1.0e-03" iyz="0.0" izz="1.0e-03"/>
    </inertial>
  </link>
  <!--  Joint 6 -->
  <joint name="joint6" type="revolute">
    <parent link="link6"/>
    <child link="link7"/>
    <origin rpy="0 0 0" xyz="0.0405 0.0 0.0"/>
    <axis xyz="0 0 1"/>
    <limit effort="1" lower="-1.790707812546182" upper="1.790707812546182" velocity="4.8"/>
  </joint>
  <!--  Link 7 -->
  <link name="link7">
    <visual>
      <origin rpy="0 0 0" xyz="0 0 0"/>
      <geometry>
        <mesh filename="package://om_urdf/meshes/stl/chain_link7_without_grippers.stl" scale="0.001 0.001 0.001"/>
      </geometry>
      <material name="grey"/>
    </visual>
    <collision>
      <origin rpy="0 0 0" xyz="0 0 0"/>
      <geometry>
        <mesh filename="package://om_urdf/meshes/stl/chain_link7_without_grippers.stl" scale="0.001 0.001 0.001"/>
      </geometry>
    </collision>
    <inertial>
      <origin xyz="0 0 0"/>
      <mass value="1.0e-03"/>
      <inertia ixx="1.0e-03" ixy="0.0" ixz="0.0" iyy="1.0e-03" iyz="0.0" izz="1.0e-03"/>
    </inertial>
  </link>
  <!--  Gripper joint -->
  <joint name="gripper" type="prismatic">
    <parent link="link7"/>
    <child link="gripper_link"/>
    <origin rpy="0 0 0" xyz="0.059 0.021 0.0"/>
    <axis xyz="0 1 0"/>
    <limit effort="1" lower="-0.010" upper="0.019" velocity="4.8"/>
  </joint>
  <!--  Gripper link -->
  <link name="gripper_link">
    <visual>
      <origin rpy="0 0 0" xyz="0.0 0.0 0"/>
      <geometry>
        <mesh filename="package://om_urdf/meshes/stl/chain_link_grip_l.stl" scale="0.001 0.001 0.001"/>
      </geometry>
      <material name="grey"/>
    </visual>
    <collision>
      <origin rpy="0 0 0" xyz="0.0 0.0 0"/>
      <geometry>
        <mesh filename="package://om_urdf/meshes/stl/chain_link_grip_l.stl" scale="0.001 0.001 0.001"/>
      </geometry>
    </collision>
    <inertial>
      <origin xyz="0 0 0"/>
      <mass value="1.0e-03"/>
      <inertia ixx="1.0e-03" ixy="0.0" ixz="0.0" iyy="1.0e-03" iyz="0.0" izz="1.0e-03"/>
    </inertial>
  </link>
  <!--  Gripper joint sub -->
  <joint name="gripper_sub" type="prismatic">
    <parent link="link7"/>
    <child link="gripper_link_sub"/>
    <origin rpy="0 0 0" xyz="0.059 -0.021 0"/>
    <axis xyz="0 -1 0"/>
    <limit effort="1" lower="-0.010" upper="0.019" velocity="4.8"/>
    <mimic joint="gripper" multiplier="1"/>
  </joint>
  <!--  Gripper link sub -->
  <link name="gripper_link_sub">
    <visual>
      <origin rpy="0 0 0" xyz="0.0 -0.0 0"/>
      <geometry>
        <mesh filename="package://om_urdf/meshes/stl/chain_link_grip_r.stl" scale="0.001 0.001 0.001"/>
      </geometry>
      <material name="grey"/>
    </visual>
    <collision>
      <origin rpy="0 0 0" xyz="0.0 -0.0 0"/>
      <geometry>
        <mesh filename="package://om_urdf/meshes/stl/chain_link_grip_r.stl" scale="0.001 0.001 0.001"/>
      </geometry>
    </collision>
    <inertial>
      <origin xyz="0 0 0"/>
      <mass value="1.0e-03"/>
      <inertia ixx="1.0e-03" ixy="0.0" ixz="0.0" iyy="1.0e-03" iyz="0.0" izz="1.0e-03"/>
    </inertial>
  </link>
  <!-- end effector joint -->
  <joint name="end_effector_joint" type="fixed">
    <origin rpy="0 0 0" xyz="0.1 0.0 0.0"/>
    <parent link="link7"/>
    <child link="end_effector_link"/>
  </joint>
  <!-- end effector link -->
  <link name="end_effector_link">
    <visual>
      <origin rpy="0 0 0" xyz="0 0 0"/>
      <geometry>
        <box size="0.01 0.01 0.01"/>
      </geometry>
      <material name="red"/>
    </visual>
    <inertial>
      <origin xyz="0 0 0"/>
      <mass value="1.0e-03"/>
      <inertia ixx="1.0e-03" ixy="0.0" ixz="0.0" iyy="1.0e-03" iyz="0.0" izz="1.0e-03"/>
    </inertial>
  </link>
</robot>

